<?xml version="1.0" ?>
<robot name="canine_RILAB">

  <material name="red">
    <color rgba="0.502 0.027 0.125 1"/>
  </material>

  <material name="black">
    <color rgba="0.2 0.2 0.2 1"/>
  </material>

  <material name="white">
    <color rgba="0.9 0.9 0.9 1"/>
  </material>

  <link name="base">
    <visual>
      <origin rpy="0 0 0" xyz="0 0 0"/>
      <geometry>
        <box size="0.001 0.001 0.001"/>
      </geometry>
    </visual>
  </link>

  <joint name="floating_base" type="fixed">
    <origin rpy="0 0 0" xyz="0 0 0"/>
    <parent link="base"/>
    <child link="trunk"/>
  </joint>

  <link name="trunk">
    <inertial>
      <origin xyz="0.05 0.0 0.0" rpy="0 0 0"/>
      <mass value="11.9704"/>
      <inertia ixx="0.1017" iyy="0.1165" izz="0.1596" ixy="0.0" iyz="0.0" ixz="0.0"/>
    </inertial>
    <visual>
      <origin xyz="0 0 0" rpy="0 0 0"/>
      <geometry>
        <mesh filename="../meshes/base_link.stl" scale="0.001 0.001 0.001"/>
      </geometry>
      <material name="red"/>
    </visual>
    <collision>
      <origin xyz="0 0 -0.011" rpy="0 0 0"/>
      <geometry>
        <box size= "0.38 0.235 0.131"/>
      </geometry>
    </collision>
  </link>

<!--Front Left-->
  <link name="FL_hip">
    <inertial>
      <origin xyz="0.059001 -0.016380 -0.000505" rpy="0 0 0"/>
      <mass value = "0.996202"/>
      <inertia ixx = "0.000916" iyy = "0.004724" izz = "0.004568" ixy = "-0.000008" iyz = "0.000963" ixz = "0.000030"/>
    </inertial>
    <visual>
      <origin xyz="-0.185613 -0.065216 -0.000494" rpy="0 0 0"/>
      <geometry>
        <mesh filename="../meshes/FL_Hip_1.stl" scale="0.001 0.001 0.001"/>
      </geometry>
      <material name="black"/>
    </visual>
    <collision>
      <origin xyz="-0.185613 -0.065216 -0.000494" rpy="0 0 0"/>
      <geometry>
        <mesh filename="../meshes/FL_Hip_1.obj" scale="0.001 0.001 0.001"/>
      </geometry>
    </collision>
  </link>

  <link name="FL_thigh">
    <inertial>
      <origin xyz="-0.002959 0.055614 -0.053931" rpy="0 0 0"/>
      <mass value = "1.400484"/>
      <inertia ixx = "0.013745" iyy = "0.009222" izz = "0.006157" ixy = "0.004784" iyz = "0.000345" ixz = "-0.000387"/>
    </inertial>
    <visual>
      <origin xyz="-0.256107 -0.062095 -0.000475" rpy="0 0 0"/>
      <geometry>
        <mesh filename="../meshes/FL_thigh_1.stl" scale="0.001 0.001 0.001"/>
      </geometry>
      <material name="black"/>
    </visual>
    <collision>
      <origin xyz="0 0.084 -0.23" rpy="1.57079632679 0 0"/>
      <geometry>
        <cylinder length="0.019" radius="0.015"/>
      </geometry>
    </collision>
  </link>

  <link name="FL_calf">
    <inertial>
      <origin xyz="0.010886 -0.010868 -0.129218" rpy="0 0 0"/>
      <mass value = "0.223676"/>
      <inertia ixx = "0.006459" iyy = "0.006480" izz = "0.000093" ixy = "-0.000314" iyz = "0.000026" ixz = "0.000313"/>
    </inertial>
    <visual>
      <origin xyz="0.256221 0.1424 0.230545" rpy="0 0 0"/>
      <geometry>
        <mesh filename="../meshes/HR_calf_1.stl" scale="0.001 0.001 0.001"/>
      </geometry>
      <material name="white"/>
    </visual>
    <collision>
      <origin xyz="0 0 -0.23" rpy="1.57079632679 0 0"/>
      <geometry>
        <sphere radius="0.025"/>
      </geometry>
    </collision>
  </link>

<!--  Front Right -->
  <link name="FR_hip">
    <inertial>
      <origin xyz="0.059001 0.016380 -0.000505" rpy="0 0 0"/>
      <mass value = "0.996202"/>
      <inertia ixx = "0.000916" iyy = "0.004724" izz = "0.004568" ixy = "0.000008" iyz = "-0.000963" ixz = "0.000030"/>
    </inertial>
    <visual>
      <origin xyz="-0.185389 0.06478 0.000488" rpy="0 0 0"/>
      <geometry>
        <mesh filename="../meshes/FR_Hip_1.stl" scale="0.001 0.001 0.001"/>
      </geometry>
      <material name="black"/>
    </visual>
    <collision>
      <origin xyz="-0.185389 0.06478 0.000488" rpy="0 0 0"/>
      <geometry>
        <mesh filename="../meshes/FR_Hip_1.obj" scale="0.001 0.001 0.001"/>
      </geometry>
    </collision>
  </link>

  <link name="FR_thigh">
    <inertial>
      <origin xyz="-0.002959 -0.055614 -0.053931" rpy="0 0 0"/>
      <mass value = "1.400484"/>
      <inertia ixx = "0.013745" iyy = "0.009222" izz = "0.006157" ixy = "-0.004784" iyz = "-0.000345" ixz = "-0.000387"/>
    </inertial>
    <visual>
      <origin xyz="-0.255894 0.061902 0.000472" rpy="0 0 0"/>
      <geometry>
        <mesh filename="../meshes/FR_thigh_1.stl" scale="0.001 0.001 0.001"/>
      </geometry>
      <material name="black"/>
    </visual>
    <collision>
      <origin xyz="0 -0.084 -0.23" rpy="1.57079632679 0 0"/>
      <geometry>
        <cylinder length="0.019" radius="0.015"/>
      </geometry>
    </collision>
  </link>

  <link name="FR_calf">
    <inertial>
      <origin xyz="0.010886 0.010868 -0.129218" rpy="0 0 0"/>
      <mass value = "0.223676"/>
      <inertia ixx = "0.006459" iyy = "0.006480" izz = "0.000093" ixy = "0.000314" iyz = "-0.000026" ixz = "0.000313"/>
    </inertial>
    <visual>
      <origin xyz="0.256221 0.1424 0.230545" rpy="0 0 0"/>
      <geometry>
        <mesh filename="../meshes/HR_calf_1.stl" scale="0.001 0.001 0.001"/>
      </geometry>
      <material name="white"/>
    </visual>
    <collision>
      <origin xyz="0 0 -0.23" rpy="1.57079632679 0 0"/>
      <geometry>
        <sphere radius="0.025"/>
      </geometry>
    </collision>
  </link>

<!--  Hind Left-->
  <link name="HL_hip">
    <inertial>
      <origin xyz="-0.059001 -0.016380 -0.000505" rpy="0 0 0"/>
      <mass value = "0.996202"/>
      <inertia ixx = "0.000916" iyy = "0.004724" izz = "0.004568" ixy = "0.000008" iyz = "0.000963" ixz = "-0.000030"/>
    </inertial>
    <visual>
      <origin xyz="0.185387 -0.065854 -0.000501" rpy="0 0 0"/>
      <geometry>
        <mesh filename="../meshes/HL_Hip_1.stl" scale="0.001 0.001 0.001"/>
      </geometry>
      <material name="black"/>
    </visual>
    <collision>
      <origin xyz="0.185387 -0.065854 -0.000501" rpy="0 0 0"/>
      <geometry>
        <mesh filename="../meshes/HL_Hip_1.obj" scale="0.001 0.001 0.001"/>
      </geometry>
    </collision>
  </link>

  <link name="HL_thigh">
    <inertial>
      <origin xyz="-0.002959 0.055614 -0.053931" rpy="0 0 0"/>
      <mass value = "1.400484"/>
      <inertia ixx = "0.013745" iyy = "0.009222" izz = "0.006157" ixy = "0.004784" iyz = "0.000345" ixz = "-0.000387"/>
    </inertial>
    <visual>
      <origin xyz="0.255892 -0.062976 -0.000485" rpy="0 0 0"/>
      <geometry>
        <mesh filename="../meshes/HL_thigh_1.stl" scale="0.001 0.001 0.001"/>
      </geometry>
      <material name="black"/>
    </visual>
    <collision>
      <origin xyz="0 0.084 -0.23" rpy="1.57079632679 0 0"/>
      <geometry>
        <cylinder length="0.019" radius="0.015"/>
      </geometry>
    </collision>
  </link>

  <link name="HL_calf">
    <inertial>
      <origin xyz="0.010886 -0.010868 -0.129218" rpy="0 0 0"/>
      <mass value = "0.223676"/>
      <inertia ixx = "0.006459" iyy = "0.006480" izz = "0.000093" ixy = "-0.000314" iyz = "0.000026" ixz = "0.000313"/>
    </inertial>
    <visual>
      <origin xyz="0.256221 0.1424 0.230545" rpy="0 0 0"/>
      <geometry>
        <mesh filename="../meshes/HR_calf_1.stl" scale="0.001 0.001 0.001"/>
      </geometry>
      <material name="white"/>
    </visual>
    <collision>
      <origin xyz="0 0 -0.23" rpy="1.57079632679 0 0"/>
      <geometry>
        <sphere radius="0.025"/>
      </geometry>
    </collision>
  </link>

<!--  Hind Right -->
  <link name="HR_hip">
    <inertial>
      <origin xyz="-0.059001 0.016380 -0.000505" rpy="0 0 0"/>
      <mass value = "0.996202"/>
      <inertia ixx = "0.000916" iyy = "0.004724" izz = "0.004568" ixy = "-0.000008" iyz = "-0.000963" ixz = "-0.000030"/>
    </inertial>
    <visual>
      <origin xyz="0.185611 0.064142 0.000481" rpy="0 0 0"/>
      <geometry>
        <mesh filename="../meshes/HR_Hip_1.stl" scale="0.001 0.001 0.001"/>
      </geometry>
      <material name="black"/>
    </visual>
    <collision>
      <origin xyz="0.185611 0.064142 0.000481" rpy="0 0 0"/>
      <geometry>
        <mesh filename="../meshes/HR_Hip_1.obj" scale="0.001 0.001 0.001"/>
      </geometry>
    </collision>
  </link>

  <link name="HR_thigh">
    <inertial>
      <origin xyz="-0.002959 -0.055614 -0.053931" rpy="0 0 0"/>
      <mass value = "1.400484"/>
      <inertia ixx = "0.013745" iyy = "0.009222" izz = "0.006157" ixy = "-0.004784" iyz = "-0.000345" ixz = "-0.000387"/>
    </inertial>
    <visual>
      <origin xyz="0.256105 0.06102 0.000462" rpy="0 0 0"/>
      <geometry>
        <mesh filename="../meshes/HR_thigh_1.stl" scale="0.001 0.001 0.001"/>
      </geometry>
      <material name="black"/>
    </visual>
    <collision>
      <origin xyz="0 -0.084 -0.23" rpy="1.57079632679 0 0"/>
      <geometry>
        <cylinder length="0.024" radius="0.025"/>
      </geometry>
    </collision>
  </link>

  <link name="HR_calf">
    <inertial>
      <origin xyz="0.010886 0.010868 -0.129218" rpy="0 0 0"/>
      <mass value = "0.223676"/>
      <inertia ixx = "0.006459" iyy = "0.006480" izz = "0.000093" ixy = "0.000314" iyz = "-0.000026" ixz = "0.000313"/>
    </inertial>
    <visual>
      <origin xyz="0.256221 0.1424 0.230545" rpy="0 0 0"/>
      <geometry>
        <mesh filename="../meshes/HR_calf_1.stl" scale="0.001 0.001 0.001"/>
      </geometry>
      <material name="white"/>
    </visual>
    <collision>
      <origin xyz="0 0 -0.23" rpy="1.57079632679 0 0"/>
      <geometry>
        <sphere radius="0.025"/>
      </geometry>
    </collision>
  </link>

  <!--  joint -->
  <joint name="FL_HIP" type="revolute">
    <origin xyz="0.1935 0.075 0.0" rpy="0 0 0"/>
    <parent link="trunk"/>
    <child link="FL_hip"/>
    <axis xyz="1 0 0"/>
  </joint>

  <joint name="FL_THIGH" type="revolute">
    <origin xyz="0.0706 -0.003 0.0" rpy="0 0 0"/>
    <parent link="FL_hip"/>
    <child link="FL_thigh"/>
    <axis xyz="0 1 0"/>
  </joint>

  <joint name="FL_KNEE" type="revolute">
    <origin xyz="0 0.085 -0.23" rpy="0 0 0"/>
    <parent link="FL_thigh"/>
    <child link="FL_calf"/>
    <axis xyz="0 1 0"/>
  </joint>

  <joint name="FR_HIP" type="revolute">
    <origin xyz="0.1935 -0.075 0.0" rpy="0 0 0"/>
    <parent link="trunk"/>
    <child link="FR_hip"/>
    <axis xyz="1 0 0"/>
  </joint>

  <joint name="FR_THIGH" type="revolute">
    <origin xyz="0.0706 0.003 0.0" rpy="0 0 0"/>
    <parent link="FR_hip"/>
    <child link="FR_thigh"/>
    <axis xyz="0 1 0"/>
  </joint>

  <joint name="FR_KNEE" type="revolute">
    <origin xyz="0 -0.085 -0.23" rpy="0 0 0"/>
    <parent link="FR_thigh"/>
    <child link="FR_calf"/>
    <axis xyz="0 1 0"/>
  </joint>

  <joint name="HL_HIP" type="revolute">
    <origin xyz="-0.1935 0.075 0.0" rpy="0 0 0"/>
    <parent link="trunk"/>
    <child link="HL_hip"/>
    <axis xyz="1 0 0"/>
  </joint>

  <joint name="HL_THIGH" type="revolute">
    <origin xyz="-0.0706 -0.003 0.0" rpy="0 0 0"/>
    <parent link="HL_hip"/>
    <child link="HL_thigh"/>
    <axis xyz="0 1 0"/>
  </joint>

  <joint name="HL_KNEE" type="revolute">
    <origin xyz="0 0.085 -0.23" rpy="0 0 0"/>
    <parent link="HL_thigh"/>
    <child link="HL_calf"/>
    <axis xyz="0 1 0"/>
  </joint>

  <joint name="HR_HIP" type="revolute">
    <origin xyz="-0.1935 -0.075 0.0" rpy="0 0 0"/>
    <parent link="trunk"/>
    <child link="HR_hip"/>
    <axis xyz="1 0 0"/>
  </joint>

  <joint name="HR_THIGH" type="revolute">
    <origin xyz="-0.0706 0.003 0.0" rpy="0 0 0"/>
    <parent link="HR_hip"/>
    <child link="HR_thigh"/>
    <axis xyz="0 1 0"/>
  </joint>

  <joint name="HR_KNEE" type="revolute">
    <origin xyz="0 -0.085 -0.23" rpy="0 0 0"/>
    <parent link="HR_thigh"/>
    <child link="HR_calf"/>
    <axis xyz="0 1 0"/>
  </joint>
</robot>